# 예외처리(exception handling)



<br>



## 1.1 프로그램 오류

<br>

**오류 또는 프로그램 에러** ➡️ 프로그램이 실행 중 어떤 원인에 의해서 오작동을 하거나 비정상적으로 종료되는 경우

<br>

에러는 크게 발생 시점에 따라서 **컴파일에러(compile-time error)**와 **런타임 에러(runtime error)**로 나눌 수 있습니다. 

> 컴파일 에러 ➡️ 컴파일 시에 발생하는 에러
>
> 런타임 에러 ➡️ 실행 시에 발생하는 에러
>
> 논리적 에러 ➡️ 실행은 되지만, 의도와 다르게 동작하는 것

소스코드를 컴파일 하면 컴파일러가 소스코드(\*.java)에 대한 오타 혹은 잘못된 구문, 자료형 체크 등의 기본적인 검사를 수행하여 오류가 있는지를 알려 줍니다. 컴파일러가 알려준 에러들을 모두 수정해서 컴파일을 성공적으로 마치고 나면, 클래스 파일(\*.class)이 생성되고, 생성된 클래스 파일을 실행할 수 있게 되는 것입니다.

그러나 컴파일을 에러없이 성공적으로 마쳤다고 해서 프로그램의 실행에 에러 발생이 없는 것은 아닙니다. **컴파일러가 소스코드의 기본적인 사항은 컴파일 시에 모두 걸러줄 수는 있지만, 실행도중에 발생할 수 있는 잠재적인 오류까지 검사할 수 없기 때문에 컴파일은 잘 되어있어도 실행 중에 에러에 의해서 잘못된 결과를 얻거나 프로그램이 비정상적으로 종료될 수 있습니다.**



<br>



> 에러(error) ➡️ 프로그램 코드에 의해서 수습될 수 없는 심각한 오류
>
> 예외(exception) ➡️ 프로그램 코드에 의해서 수습될 수 있는 다소 미약한 오류



<br>

## 1.2 예외 클래스의 계층구조





<br>



> `RuntimeException` 클래스들 ➡️ 프로그래머의 실수로 발생하는 예외[`예외처리 필수`]
>
> `Exception` 클래스들 ➡️사용자의 실수와 같은 외적인 요인에 의해 발생하는 예외[`예외처리 선택`]

예외 클래스 또한 `Object` 클래스의 자손입니다. 아래와 같이 `Exception` 클래스의 자손으로 `RuntimeException` 클래스와 그 자손들이 있습니다.

<img src="C:\Users\piay8\AppData\Roaming\Typora\typora-user-images\image-20220727193451642.png" alt="image-20220727193451642" style="zoom:80%;" />

<img src="C:\Users\piay8\AppData\Roaming\Typora\typora-user-images\image-20220727193457606.png" alt="image-20220727193457606" style="zoom:80%;" />



<br>



## 1.3 예외처리하기 - try - catch 문



<br>

발생한 예외를 처리하지 못하면, 프로그램은 비정상적으로 종료되며, 처리되지 못한 예외(`uncaught exception`)는 JVM의 "예외처리기(`UncaughtExceptionHandler`)"가 받아서 예외의 원인을 화면에 출력합니다.



<br>



> **예외처리(exception handling)**
>
> **정의** ➡️ 프로그램 실행 시 발생할 수 있는 예외에 대비한 코드를 작성하는 것
>
> **목적** ➡️ 프로그램의 비정상 종료를 막고, 정상적으로 실행상태를 유지하는 것



<br>

하나의 `try` 블럭 다음으로 여러 종류의 예외를 처리할 수 있도록 하나 이상의 `catch` 블럭이 올 수 있으며, 이 중 발생한 예외의 종류와 일치하는 단 한 개의 `catch` 블럭만 수행됩니다. 발생한 예외의 종류와 일치하는 `catch` 블럭이 없으면 예외는 처리되지 않습니다.

```java
try {
    // 예외가 발생할 가능성이 있는 문장들을 넣는다.
} catch (Exception1 e1) {
    // Exception1이 발생했을 경우, 이를 처리하기 위한 문장을 적는다.
} catch (Exception2 e2) {
   // Exception2이 발생했을 경우, 이를 처리하기 위한 문장을 적는다.
} catch (ExceptionN eN) {
    // ExceptionN이 발생했을 경우, 이를 처리하기 위한 문장을 적는다.
}
```

👻`if`문과 다르게, `try`블럭 또는 `catch`블럭 내에 포함된 문장이 하나뿐이어도 괄호 `{}`를 생략할 수 없다.



<br>

일단, 아래의 코드는 단순히 `try-catch`문의 사용 예를 보여 주기 위해서 작성한 코드입니다. 이처럼 하나의 메서드 내에 여러 개의 `try-catch`문이 사용될 수 있고, `try`블럭 또는 `catch`블럭에 또 다른 `try-catch`문이 포함될 수 있습니다. **`catch`블럭 내의 코드에서도 예외가 발생할 수 있기 때문이에요.** 

`catch` 블럭 내에 또 하나의 `try-catch`문이 포함된 경우, 같은 이름의 참조변수를 사용해서는 안됩니다. 각 `catch`블럭에 서언된 두 참조변수의 영역이 서로 겹츠므로 다른 이름을 사용해야만 서로 구별되기 때문입니다. 따라서 아래의 `catch`블럭 내의 `try-catch`문에 선언되어 있는 참조변수의 이름을 `e`가 아닌 다른 것으로 바꿔야 합니다.

~~~java
public class ExceptionEx1 {
    public static void main(String[] args) {
        try {
            try { } catch (Exception e) { }
        } catch (Exception e) {
                try { } catch (Exception e) { } // 에러. 변수 e가 중복 선언되었습니다.
            }   // try-catch 의 끝

        try {

        } catch (Exception e) {

        } // try-catch 의 끝
    } // main 메서드의 끝
}
~~~



<br>



## 1.4 try-catch문에서의 흐름



<br>



`try-catch`문에서, 예외가 발생한 경우와 발생하지 않았을 때의 흐름(문장의 실행순서)이 달라지는데, 아래에 이 두 가지 경우에 따른 문장 실행순서를 정리합니다. 

> try블럭 내에서 예외가 발생한 경우
>
> 1. 발생한 예외와 일치하는 catch블럭이 있는지 확인합니다.
> 2. 일치하는 `catch`블럭을 찾게 되면, 그 `catch`블럭 내의 문장들을 수행하고 전체 `try-catch`문을 빠져나가서 그 다음 문장을 계속해서 수행합니다. 만일 일치하는 `catch` 블럭을 찾지 못하면, 예외는 처리되지 않는다.
>
> try 블럭 내에서 예외가 발생하지 않은 경우
>
> 1. catch블럭을 거치지 않고 전체 `try-catch`문을 빠져나가서 수행을 계속한다



<br>

### 정상적인 경우

예외가 발생하지 않을 때, `catch` 블럭의 문장은 실행되지 않습니다. 아래의 코드를 통해서 정상적인 경우를 먼저 살펴보겠습니다.

~~~java
public class ExceptionEx4 {
    public static void main(String[] args) {
        System.out.println(1);
        System.out.println(2);
        
        try {
            System.out.println(3);
            System.out.println(4);
        } catch (Exception e) {
            System.out.println(5);  // 실행되지 않는다.
        }   // try - catch 의 끝
        System.out.println(6);
    }   // main 메서드 끝
}

~~~

~~~java
/* 실행결과 */
1
2
3
4
6
~~~



<br>

### 예외 발생하는 경우

고의적으로 `0/0` 을 출력하도록 하고, 출력되는 결과를 보는 코드를 작성했습니다. 아래의 코드처럼 예외가 발생되는 코드를 만나게 될 때, `catch` 문의 블럭으로 넘어가고 바로 아래의 `System.out.println(4);` 는 수행되지 않게 됩니다. 

~~~java
public class ExceptionEx5 {
    public static void main(String[] args) {
        System.out.println(1);
        System.out.println(2);
        try {
            System.out.println(3);
            System.out.println(0/0); // 0 으로 나눠서 고의로 ArithmeticException 을 발생시킵니다.
            System.out.println(4);  // 실행되지 않습니다.
        } catch (ArithmeticException ae) {
            System.out.println(5);
        }   // try - catch 의 끝
        System.out.println(6);
    }
}

~~~

~~~java
/* 실행 결과 */
1
2
3
5
6
~~~



<br>

## 1.5 예외의 발생과 catch 블럭

<br>

> `printStackTrace()` 예외발생 당시의 호출스택(Call Stack)에 있었던 메서드의 정보와 예외 메세지를 화면에 출력한다.
>
> `getMessage()` 발생한 예외클래스의 인스턴스에 저장된 메세지를 얻을 수 있다.

<br>

~~~java
public class ExceptionEx8 {
    public static void main(String[] args) {
        System.out.println(1);
        System.out.println(2);
        try {
            System.out.println(3);
            System.out.println(0/0);
            System.out.println(4);
        } catch (ArithmeticException ae) {
            ae.printStackTrace();
            System.out.println("예외메세지 : " + ae.getMessage() );
        }   // try - catch 의 끝
        System.out.println(6);
    } // main 메서드의 끝
}

~~~

~~~java
/* 실행 결과 */
1
2
3
예외메세지 : / by zero
6
java.lang.ArithmeticException: / by zero
	at ExceptionEx8.main(ExceptionEx8.java:7)

~~~



<br>

### 멀티 catch 블럭

JDK1.7부터 여러 catch블럭을 `|` 기호를 이용해서, 하나의 catch 블럭으로 합칠 수 있게 되었으며, 이를 "멀티 catch블럭" 이라고 합니다. 아래의 코드에서 알 수 있듯이 "멀티 catch블럭"을 이용하면 중복된 코드를 줄일 수 있습니다. 그리고 `|` 기호로 연결할 수 있는 예외 클래스의 개수에는 제한이 없습니다.

~~~java
/* JDK 1.7 이전 */
try {
...
} catch (ExceptionA e) {
    e.printStackTrace();
} catch (Exception e2) {
    e2.printStackTrace();
}

/* JDK 1.7 이후 */
try {
    ...
} catch (ExceptionA | Exception e) {
    e.printStackTrace();
}
~~~



<br>

## 1.6 예외 발생시키기

<br>

키워드 `throw`를 사용해서 프로그래머가 고의로 예외를 발생시킬 수 있으며, 방법은 아래의 순서과 같습니다.

> 1. 연산자 `new`를 이용해서 발생시키려는 예외클래스의 객체를 생성
>
>    `Exception e = new Exception("고의로 발생시켰음");`
>
> 2. 키워드 `throw`를 이용해서 예외를 발생시킨다.
>
>    `throw e;`



<br>

~~~java
public class ExceptionEx9 {
    public static void main(String[] args) {
        try {
            Exception e = new Exception("고의로 발생시켰음.");
            throw e;    // 예외를 발생시킴
//            throw new Exception("고의로 발생시켰음.");
        } catch (Exception e) {
            System.out.println("에러 메세지 : " + e.getMessage());
            e.printStackTrace();
        }
        System.out.println("프로그램이 정상 종료되었음.");
    }
}

~~~

~~~java
/* 실행 결과 */
에러 메세지 : 고의로 발생시켰음.
프로그램이 정상 종료되었음.
java.lang.Exception: 고의로 발생시켰음.
	at ExceptionEx9.main(ExceptionEx9.java:4)

~~~





<br>

## 1.8 finally 블럭

<br>

`finally` 블럭은 예외의 발생여부에 상관없이 실행되어야할 코드를 포함시킬 목적으로 사용됩니다. `try - catch`문의 끝에 선택적으로 덧붙여 사용할 수 있으며, `try-catch-finally`의 순서로 구성이 됩니다.

~~~java
try {
    // 예외가 발생할 가능성이 있는 문장들을 넣습니다.
} catch (Exception e1) {
    // 예외처리를 위한 문장을 적습니다.
} finally {
    // 예외의 발생여부에 관계없이 항상 수행되어야하는 문장들을 넣습니다.
    // finally 블럭은 try-catch문의 맨 마지막에 위치해야 합니다.
}
~~~

예외가 발생한 경우에는 `try` ➡️ `catch` ➡️ `finally` 의 순서대로 실행이 되고, 예외가 발생하지 않는 경우에는 `try` ➡️ `finally` 순으로 실행이 됩니다.

<br>

~~~java
public class FinallyTest {
    public static void main(String[] args) {
        try {
            startInstall();
            copyFiles();
            deleteTempFiles();
        }  catch (Exception e) {
            e.printStackTrace();
            deleteTempFiles();
        }   // try-catch 의 끝
    }   // main 의 끝
    static void startInstall() { /* 프로그램 설치에 필요한 준비를 하는 코드를 적는다.*/}
    static void copyFiles() { /* 파일들을 복사하는 코드를 적는다. */}
    static void deleteTempFiles() { /* 임시파일들을 삭제하는 코드를 적는다. */ }
}

~~~

프로그램의 설치과정 중에 예외가 발생하더라도, 설치에 사용된 임시파일들이 삭제되도록 `catch` 블럭에 `deleteTempFiles()` 메서드를 넣었습니다. 결국 `try` 블럭의 문장을 수행하는 동안에(프로그램을 설치하는 과정에), 예외의 발생여부에 관계없이 `deleteTempFiles()` 메서드는 실행되어야 하는 것입니다.

이럴 때, `finally` 블럭을 사용하면 좋습니다! 아래처럼 작성하면 `deleteTempFiles();`가 실행되겠죠?

~~~java
public class FinallyTest2 {
    public static void main(String[] args) {
        try {
            startInstall();
            copyFiles();
        }  catch (Exception e) {
            e.printStackTrace();
        }  finally { // try-catch 의 끝에 finally
            deleteTempFiles();
        }
    }   // main 의 끝
    static void startInstall() { /* 프로그램 설치에 필요한 준비를 하는 코드를 적는다.*/}
    static void copyFiles() { /* 파일들을 복사하는 코드를 적는다. */}
    static void deleteTempFiles() { /* 임시파일들을 삭제하는 코드를 적는다. */ }
}

~~~





























































